[2022-08-11 19:27:09,915] {taskinstance.py:1179} INFO - Dependencies all met for <TaskInstance: ETL_DAG_V2.Ingest_from_current_food_expenditure_series manual__2022-08-11T05:57:31.582348+00:00 [queued]>
[2022-08-11 19:27:09,934] {taskinstance.py:1179} INFO - Dependencies all met for <TaskInstance: ETL_DAG_V2.Ingest_from_current_food_expenditure_series manual__2022-08-11T05:57:31.582348+00:00 [queued]>
[2022-08-11 19:27:09,935] {taskinstance.py:1376} INFO - 
--------------------------------------------------------------------------------
[2022-08-11 19:27:09,939] {taskinstance.py:1377} INFO - Starting attempt 3 of 6
[2022-08-11 19:27:09,940] {taskinstance.py:1378} INFO - 
--------------------------------------------------------------------------------
[2022-08-11 19:27:09,958] {taskinstance.py:1397} INFO - Executing <Task(PythonOperator): Ingest_from_current_food_expenditure_series> on 2022-08-11 05:57:31.582348+00:00
[2022-08-11 19:27:09,965] {standard_task_runner.py:52} INFO - Started process 2312 to run task
[2022-08-11 19:27:09,971] {standard_task_runner.py:79} INFO - Running: ['***', 'tasks', 'run', 'ETL_DAG_V2', 'Ingest_from_current_food_expenditure_series', 'manual__2022-08-11T05:57:31.582348+00:00', '--job-id', '495', '--raw', '--subdir', 'DAGS_FOLDER/etl_dag.py', '--cfg-path', '/tmp/tmpvrnzfmfl', '--error-file', '/tmp/tmp2_dwes2l']
[2022-08-11 19:27:09,974] {standard_task_runner.py:80} INFO - Job 495: Subtask Ingest_from_current_food_expenditure_series
[2022-08-11 19:27:10,037] {task_command.py:371} INFO - Running <TaskInstance: ETL_DAG_V2.Ingest_from_current_food_expenditure_series manual__2022-08-11T05:57:31.582348+00:00 [running]> on host ce1be8c59d56
[2022-08-11 19:27:10,102] {taskinstance.py:1591} INFO - Exporting the following env vars:
AIRFLOW_CTX_DAG_OWNER=narapady
AIRFLOW_CTX_DAG_ID=ETL_DAG_V2
AIRFLOW_CTX_TASK_ID=Ingest_from_current_food_expenditure_series
AIRFLOW_CTX_EXECUTION_DATE=2022-08-11T05:57:31.582348+00:00
AIRFLOW_CTX_TRY_NUMBER=3
AIRFLOW_CTX_DAG_RUN_ID=manual__2022-08-11T05:57:31.582348+00:00
[2022-08-11 19:27:10,146] {taskinstance.py:1909} ERROR - Task failed with exception
Traceback (most recent call last):
  File "/home/airflow/.local/lib/python3.7/site-packages/airflow/operators/python.py", line 171, in execute
    return_value = self.execute_callable()
  File "/home/airflow/.local/lib/python3.7/site-packages/airflow/operators/python.py", line 189, in execute_callable
    return self.python_callable(*self.op_args, **self.op_kwargs)
  File "/opt/airflow/dags/ingest/ingestor.py", line 124, in run
    if usda:
NameError: name 'usda' is not defined
[2022-08-11 19:27:10,161] {taskinstance.py:1420} INFO - Marking task as UP_FOR_RETRY. dag_id=ETL_DAG_V2, task_id=Ingest_from_current_food_expenditure_series, execution_date=20220811T055731, start_date=20220811T192709, end_date=20220811T192710
[2022-08-11 19:27:10,175] {standard_task_runner.py:97} ERROR - Failed to execute job 495 for task Ingest_from_current_food_expenditure_series (name 'usda' is not defined; 2312)
[2022-08-11 19:27:10,223] {local_task_job.py:156} INFO - Task exited with return code 1
[2022-08-11 19:27:10,258] {local_task_job.py:273} INFO - 0 downstream tasks scheduled from follow-on schedule check
