[2022-08-11 19:27:09,833] {taskinstance.py:1179} INFO - Dependencies all met for <TaskInstance: ETL_DAG_V2.Ingest_from_nutrient_intake_estimates manual__2022-08-11T00:39:54.349266+00:00 [queued]>
[2022-08-11 19:27:09,846] {taskinstance.py:1179} INFO - Dependencies all met for <TaskInstance: ETL_DAG_V2.Ingest_from_nutrient_intake_estimates manual__2022-08-11T00:39:54.349266+00:00 [queued]>
[2022-08-11 19:27:09,848] {taskinstance.py:1376} INFO - 
--------------------------------------------------------------------------------
[2022-08-11 19:27:09,849] {taskinstance.py:1377} INFO - Starting attempt 3 of 6
[2022-08-11 19:27:09,850] {taskinstance.py:1378} INFO - 
--------------------------------------------------------------------------------
[2022-08-11 19:27:09,866] {taskinstance.py:1397} INFO - Executing <Task(PythonOperator): Ingest_from_nutrient_intake_estimates> on 2022-08-11 00:39:54.349266+00:00
[2022-08-11 19:27:09,873] {standard_task_runner.py:52} INFO - Started process 2310 to run task
[2022-08-11 19:27:09,879] {standard_task_runner.py:79} INFO - Running: ['***', 'tasks', 'run', 'ETL_DAG_V2', 'Ingest_from_nutrient_intake_estimates', 'manual__2022-08-11T00:39:54.349266+00:00', '--job-id', '493', '--raw', '--subdir', 'DAGS_FOLDER/etl_dag.py', '--cfg-path', '/tmp/tmp8rvuczwk', '--error-file', '/tmp/tmpcm375eo_']
[2022-08-11 19:27:09,883] {standard_task_runner.py:80} INFO - Job 493: Subtask Ingest_from_nutrient_intake_estimates
[2022-08-11 19:27:09,981] {task_command.py:371} INFO - Running <TaskInstance: ETL_DAG_V2.Ingest_from_nutrient_intake_estimates manual__2022-08-11T00:39:54.349266+00:00 [running]> on host ce1be8c59d56
[2022-08-11 19:27:10,078] {taskinstance.py:1591} INFO - Exporting the following env vars:
AIRFLOW_CTX_DAG_OWNER=narapady
AIRFLOW_CTX_DAG_ID=ETL_DAG_V2
AIRFLOW_CTX_TASK_ID=Ingest_from_nutrient_intake_estimates
AIRFLOW_CTX_EXECUTION_DATE=2022-08-11T00:39:54.349266+00:00
AIRFLOW_CTX_TRY_NUMBER=3
AIRFLOW_CTX_DAG_RUN_ID=manual__2022-08-11T00:39:54.349266+00:00
[2022-08-11 19:27:10,123] {taskinstance.py:1909} ERROR - Task failed with exception
Traceback (most recent call last):
  File "/home/airflow/.local/lib/python3.7/site-packages/airflow/operators/python.py", line 171, in execute
    return_value = self.execute_callable()
  File "/home/airflow/.local/lib/python3.7/site-packages/airflow/operators/python.py", line 189, in execute_callable
    return self.python_callable(*self.op_args, **self.op_kwargs)
  File "/opt/airflow/dags/ingest/ingestor.py", line 124, in run
    if usda:
NameError: name 'usda' is not defined
[2022-08-11 19:27:10,137] {taskinstance.py:1420} INFO - Marking task as UP_FOR_RETRY. dag_id=ETL_DAG_V2, task_id=Ingest_from_nutrient_intake_estimates, execution_date=20220811T003954, start_date=20220811T192709, end_date=20220811T192710
[2022-08-11 19:27:10,147] {standard_task_runner.py:97} ERROR - Failed to execute job 493 for task Ingest_from_nutrient_intake_estimates (name 'usda' is not defined; 2310)
[2022-08-11 19:27:10,170] {local_task_job.py:156} INFO - Task exited with return code 1
[2022-08-11 19:27:10,206] {local_task_job.py:273} INFO - 0 downstream tasks scheduled from follow-on schedule check
