[2022-08-11 19:39:17,783] {taskinstance.py:1179} INFO - Dependencies all met for <TaskInstance: ETL_DAG_V3.Ingest_from_current_food_expenditure_series manual__2022-08-11T19:39:13.033032+00:00 [queued]>
[2022-08-11 19:39:17,805] {taskinstance.py:1179} INFO - Dependencies all met for <TaskInstance: ETL_DAG_V3.Ingest_from_current_food_expenditure_series manual__2022-08-11T19:39:13.033032+00:00 [queued]>
[2022-08-11 19:39:17,807] {taskinstance.py:1376} INFO - 
--------------------------------------------------------------------------------
[2022-08-11 19:39:17,808] {taskinstance.py:1377} INFO - Starting attempt 1 of 6
[2022-08-11 19:39:17,809] {taskinstance.py:1378} INFO - 
--------------------------------------------------------------------------------
[2022-08-11 19:39:17,834] {taskinstance.py:1397} INFO - Executing <Task(PythonOperator): Ingest_from_current_food_expenditure_series> on 2022-08-11 19:39:13.033032+00:00
[2022-08-11 19:39:17,847] {standard_task_runner.py:79} INFO - Running: ['***', 'tasks', 'run', 'ETL_DAG_V3', 'Ingest_from_current_food_expenditure_series', 'manual__2022-08-11T19:39:13.033032+00:00', '--job-id', '528', '--raw', '--subdir', 'DAGS_FOLDER/etl_dag.py', '--cfg-path', '/tmp/tmpp4lu802x', '--error-file', '/tmp/tmpr7qupm8k']
[2022-08-11 19:39:17,842] {standard_task_runner.py:52} INFO - Started process 3244 to run task
[2022-08-11 19:39:17,852] {standard_task_runner.py:80} INFO - Job 528: Subtask Ingest_from_current_food_expenditure_series
[2022-08-11 19:39:17,973] {task_command.py:371} INFO - Running <TaskInstance: ETL_DAG_V3.Ingest_from_current_food_expenditure_series manual__2022-08-11T19:39:13.033032+00:00 [running]> on host ce1be8c59d56
[2022-08-11 19:39:18,075] {taskinstance.py:1591} INFO - Exporting the following env vars:
AIRFLOW_CTX_DAG_OWNER=narapady
AIRFLOW_CTX_DAG_ID=ETL_DAG_V3
AIRFLOW_CTX_TASK_ID=Ingest_from_current_food_expenditure_series
AIRFLOW_CTX_EXECUTION_DATE=2022-08-11T19:39:13.033032+00:00
AIRFLOW_CTX_TRY_NUMBER=1
AIRFLOW_CTX_DAG_RUN_ID=manual__2022-08-11T19:39:13.033032+00:00
[2022-08-11 19:39:25,088] {taskinstance.py:1909} ERROR - Task failed with exception
Traceback (most recent call last):
  File "/home/airflow/.local/lib/python3.7/site-packages/airflow/operators/python.py", line 171, in execute
    return_value = self.execute_callable()
  File "/home/airflow/.local/lib/python3.7/site-packages/airflow/operators/python.py", line 189, in execute_callable
    return self.python_callable(*self.op_args, **self.op_kwargs)
  File "/opt/airflow/dags/ingest/ingestor.py", line 132, in run
    ingestor_usda.ingest()
  File "/opt/airflow/dags/ingest/ingestor.py", line 115, in ingest
    ingest_usda(self.s3, self.source, self.bucket_name, self.category)
  File "/opt/airflow/dags/ingest/ingestor.py", line 61, in ingest_usda
    links = filter_links(source_list)[category]
KeyError: 'current_food_expenditure_series'
[2022-08-11 19:39:25,098] {taskinstance.py:1420} INFO - Marking task as UP_FOR_RETRY. dag_id=ETL_DAG_V3, task_id=Ingest_from_current_food_expenditure_series, execution_date=20220811T193913, start_date=20220811T193917, end_date=20220811T193925
[2022-08-11 19:39:25,107] {standard_task_runner.py:97} ERROR - Failed to execute job 528 for task Ingest_from_current_food_expenditure_series ('current_food_expenditure_series'; 3244)
[2022-08-11 19:39:25,126] {local_task_job.py:156} INFO - Task exited with return code 1
[2022-08-11 19:39:25,154] {local_task_job.py:273} INFO - 0 downstream tasks scheduled from follow-on schedule check
