[2022-08-12 04:42:13,829] {taskinstance.py:1179} INFO - Dependencies all met for <TaskInstance: ETL_DAG_US_FOOD_NUTRITION.Ingest_from_loss-adjusted_food_availability manual__2022-08-12T04:42:08.092521+00:00 [queued]>
[2022-08-12 04:42:13,857] {taskinstance.py:1179} INFO - Dependencies all met for <TaskInstance: ETL_DAG_US_FOOD_NUTRITION.Ingest_from_loss-adjusted_food_availability manual__2022-08-12T04:42:08.092521+00:00 [queued]>
[2022-08-12 04:42:13,860] {taskinstance.py:1376} INFO - 
--------------------------------------------------------------------------------
[2022-08-12 04:42:13,861] {taskinstance.py:1377} INFO - Starting attempt 1 of 6
[2022-08-12 04:42:13,862] {taskinstance.py:1378} INFO - 
--------------------------------------------------------------------------------
[2022-08-12 04:42:13,876] {taskinstance.py:1397} INFO - Executing <Task(PythonOperator): Ingest_from_loss-adjusted_food_availability> on 2022-08-12 04:42:08.092521+00:00
[2022-08-12 04:42:13,884] {standard_task_runner.py:52} INFO - Started process 8687 to run task
[2022-08-12 04:42:13,895] {standard_task_runner.py:79} INFO - Running: ['***', 'tasks', 'run', 'ETL_DAG_US_FOOD_NUTRITION', 'Ingest_from_loss-adjusted_food_availability', 'manual__2022-08-12T04:42:08.092521+00:00', '--job-id', '791', '--raw', '--subdir', 'DAGS_FOLDER/etl_dag.py', '--cfg-path', '/tmp/tmpkxqqhymd', '--error-file', '/tmp/tmpwkrtx6ue']
[2022-08-12 04:42:13,899] {standard_task_runner.py:80} INFO - Job 791: Subtask Ingest_from_loss-adjusted_food_availability
[2022-08-12 04:42:14,009] {task_command.py:371} INFO - Running <TaskInstance: ETL_DAG_US_FOOD_NUTRITION.Ingest_from_loss-adjusted_food_availability manual__2022-08-12T04:42:08.092521+00:00 [running]> on host ae5c2449a624
[2022-08-12 04:42:14,130] {taskinstance.py:1591} INFO - Exporting the following env vars:
AIRFLOW_CTX_DAG_OWNER=narapady
AIRFLOW_CTX_DAG_ID=ETL_DAG_US_FOOD_NUTRITION
AIRFLOW_CTX_TASK_ID=Ingest_from_loss-adjusted_food_availability
AIRFLOW_CTX_EXECUTION_DATE=2022-08-12T04:42:08.092521+00:00
AIRFLOW_CTX_TRY_NUMBER=1
AIRFLOW_CTX_DAG_RUN_ID=manual__2022-08-12T04:42:08.092521+00:00
[2022-08-12 04:42:28,870] {logging_mixin.py:115} INFO - Successfully uploaded loss-adjusted-food-availability/calories.xls to s3-bucket-raw-usda
[2022-08-12 04:43:06,505] {logging_mixin.py:115} INFO - Successfully uploaded loss-adjusted-food-availability/Dairy.xls to s3-bucket-raw-usda
[2022-08-12 04:43:16,467] {logging_mixin.py:115} INFO - Successfully uploaded loss-adjusted-food-availability/fat.xls to s3-bucket-raw-usda
[2022-08-12 04:43:26,401] {logging_mixin.py:115} INFO - Successfully uploaded loss-adjusted-food-availability/servings.xls to s3-bucket-raw-usda
[2022-08-12 04:44:16,380] {logging_mixin.py:115} INFO - Successfully uploaded loss-adjusted-food-availability/Fruit.xls to s3-bucket-raw-usda
[2022-08-12 04:44:28,600] {logging_mixin.py:115} INFO - Successfully uploaded loss-adjusted-food-availability/grain.xls to s3-bucket-raw-usda
[2022-08-12 05:11:05,557] {local_task_job.py:221} WARNING - State of this instance has been externally set to failed. Terminating instance.
[2022-08-12 05:11:05,580] {process_utils.py:129} INFO - Sending Signals.SIGTERM to group 8687. PIDs of all processes in the group: [8687]
[2022-08-12 05:11:05,581] {process_utils.py:80} INFO - Sending the signal Signals.SIGTERM to group 8687
[2022-08-12 05:11:05,584] {taskinstance.py:1561} ERROR - Received SIGTERM. Terminating subprocesses.
[2022-08-12 05:11:05,717] {process_utils.py:75} INFO - Process psutil.Process(pid=8687, status='terminated', exitcode=0, started='04:42:13') (8687) terminated with exit code 0
