[2022-08-08 20:08:29,009] {taskinstance.py:1179} INFO - Dependencies all met for <TaskInstance: etl_dag_v5.Stager manual__2022-08-08T20:06:59.253743+00:00 [queued]>
[2022-08-08 20:08:29,015] {taskinstance.py:1179} INFO - Dependencies all met for <TaskInstance: etl_dag_v5.Stager manual__2022-08-08T20:06:59.253743+00:00 [queued]>
[2022-08-08 20:08:29,016] {taskinstance.py:1376} INFO - 
--------------------------------------------------------------------------------
[2022-08-08 20:08:29,017] {taskinstance.py:1377} INFO - Starting attempt 1 of 6
[2022-08-08 20:08:29,019] {taskinstance.py:1378} INFO - 
--------------------------------------------------------------------------------
[2022-08-08 20:08:29,028] {taskinstance.py:1397} INFO - Executing <Task(PythonOperator): Stager> on 2022-08-08 20:06:59.253743+00:00
[2022-08-08 20:08:29,033] {standard_task_runner.py:52} INFO - Started process 13567 to run task
[2022-08-08 20:08:29,036] {standard_task_runner.py:79} INFO - Running: ['***', 'tasks', 'run', 'etl_dag_v5', 'Stager', 'manual__2022-08-08T20:06:59.253743+00:00', '--job-id', '97', '--raw', '--subdir', 'DAGS_FOLDER/etl_dag.py', '--cfg-path', '/tmp/tmpegemv1nw', '--error-file', '/tmp/tmpd6yw_con']
[2022-08-08 20:08:29,038] {standard_task_runner.py:80} INFO - Job 97: Subtask Stager
[2022-08-08 20:08:29,082] {task_command.py:371} INFO - Running <TaskInstance: etl_dag_v5.Stager manual__2022-08-08T20:06:59.253743+00:00 [running]> on host 8d3924a1d70c
[2022-08-08 20:08:29,124] {taskinstance.py:1591} INFO - Exporting the following env vars:
AIRFLOW_CTX_DAG_OWNER=narapady
AIRFLOW_CTX_DAG_ID=etl_dag_v5
AIRFLOW_CTX_TASK_ID=Stager
AIRFLOW_CTX_EXECUTION_DATE=2022-08-08T20:06:59.253743+00:00
AIRFLOW_CTX_TRY_NUMBER=1
AIRFLOW_CTX_DAG_RUN_ID=manual__2022-08-08T20:06:59.253743+00:00
[2022-08-08 20:08:29,882] {taskinstance.py:1909} ERROR - Task failed with exception
Traceback (most recent call last):
  File "/home/airflow/.local/lib/python3.7/site-packages/airflow/operators/python.py", line 171, in execute
    return_value = self.execute_callable()
  File "/home/airflow/.local/lib/python3.7/site-packages/airflow/operators/python.py", line 189, in execute_callable
    return self.python_callable(*self.op_args, **self.op_kwargs)
  File "/opt/airflow/dags/stage/stager.py", line 167, in run
    stager.run()
AttributeError: 'Stager' object has no attribute 'run'
[2022-08-08 20:08:29,890] {taskinstance.py:1420} INFO - Marking task as UP_FOR_RETRY. dag_id=etl_dag_v5, task_id=Stager, execution_date=20220808T200659, start_date=20220808T200829, end_date=20220808T200829
[2022-08-08 20:08:29,898] {standard_task_runner.py:97} ERROR - Failed to execute job 97 for task Stager ('Stager' object has no attribute 'run'; 13567)
[2022-08-08 20:08:29,913] {local_task_job.py:156} INFO - Task exited with return code 1
[2022-08-08 20:08:29,937] {local_task_job.py:273} INFO - 0 downstream tasks scheduled from follow-on schedule check
