[2022-08-11 19:22:00,249] {taskinstance.py:1179} INFO - Dependencies all met for <TaskInstance: ETL_DAG_V2.Ingest_from_current_food_expenditure_series manual__2022-08-11T00:39:54.349266+00:00 [queued]>
[2022-08-11 19:22:00,260] {taskinstance.py:1179} INFO - Dependencies all met for <TaskInstance: ETL_DAG_V2.Ingest_from_current_food_expenditure_series manual__2022-08-11T00:39:54.349266+00:00 [queued]>
[2022-08-11 19:22:00,261] {taskinstance.py:1376} INFO - 
--------------------------------------------------------------------------------
[2022-08-11 19:22:00,262] {taskinstance.py:1377} INFO - Starting attempt 2 of 6
[2022-08-11 19:22:00,263] {taskinstance.py:1378} INFO - 
--------------------------------------------------------------------------------
[2022-08-11 19:22:00,273] {taskinstance.py:1397} INFO - Executing <Task(PythonOperator): Ingest_from_current_food_expenditure_series> on 2022-08-11 00:39:54.349266+00:00
[2022-08-11 19:22:00,282] {standard_task_runner.py:52} INFO - Started process 1889 to run task
[2022-08-11 19:22:00,284] {standard_task_runner.py:79} INFO - Running: ['***', 'tasks', 'run', 'ETL_DAG_V2', 'Ingest_from_current_food_expenditure_series', 'manual__2022-08-11T00:39:54.349266+00:00', '--job-id', '470', '--raw', '--subdir', 'DAGS_FOLDER/etl_dag.py', '--cfg-path', '/tmp/tmpjbrrnm04', '--error-file', '/tmp/tmp5j6es57x']
[2022-08-11 19:22:00,287] {standard_task_runner.py:80} INFO - Job 470: Subtask Ingest_from_current_food_expenditure_series
[2022-08-11 19:22:00,342] {task_command.py:371} INFO - Running <TaskInstance: ETL_DAG_V2.Ingest_from_current_food_expenditure_series manual__2022-08-11T00:39:54.349266+00:00 [running]> on host ce1be8c59d56
[2022-08-11 19:22:00,397] {taskinstance.py:1591} INFO - Exporting the following env vars:
AIRFLOW_CTX_DAG_OWNER=narapady
AIRFLOW_CTX_DAG_ID=ETL_DAG_V2
AIRFLOW_CTX_TASK_ID=Ingest_from_current_food_expenditure_series
AIRFLOW_CTX_EXECUTION_DATE=2022-08-11T00:39:54.349266+00:00
AIRFLOW_CTX_TRY_NUMBER=2
AIRFLOW_CTX_DAG_RUN_ID=manual__2022-08-11T00:39:54.349266+00:00
[2022-08-11 19:22:07,525] {taskinstance.py:1909} ERROR - Task failed with exception
Traceback (most recent call last):
  File "/home/airflow/.local/lib/python3.7/site-packages/airflow/operators/python.py", line 171, in execute
    return_value = self.execute_callable()
  File "/home/airflow/.local/lib/python3.7/site-packages/airflow/operators/python.py", line 189, in execute_callable
    return self.python_callable(*self.op_args, **self.op_kwargs)
  File "/opt/airflow/dags/ingest/ingestor.py", line 129, in run
    ingestor_usda.ingest()
  File "/opt/airflow/dags/ingest/ingestor.py", line 111, in ingest
    ingest_usda(self.s3, self.source, self.bucket_name, self.category)
  File "/opt/airflow/dags/ingest/ingestor.py", line 61, in ingest_usda
    links = filter_links(source_list)[category]
KeyError: 'current_food_expenditure_series'
[2022-08-11 19:22:07,535] {taskinstance.py:1420} INFO - Marking task as UP_FOR_RETRY. dag_id=ETL_DAG_V2, task_id=Ingest_from_current_food_expenditure_series, execution_date=20220811T003954, start_date=20220811T192200, end_date=20220811T192207
[2022-08-11 19:22:07,544] {standard_task_runner.py:97} ERROR - Failed to execute job 470 for task Ingest_from_current_food_expenditure_series ('current_food_expenditure_series'; 1889)
[2022-08-11 19:22:07,582] {local_task_job.py:156} INFO - Task exited with return code 1
[2022-08-11 19:22:07,608] {local_task_job.py:273} INFO - 0 downstream tasks scheduled from follow-on schedule check
