[2022-08-11 19:25:00,305] {taskinstance.py:1179} INFO - Dependencies all met for <TaskInstance: ETL_DAG_V2.Ingest_from_food_consumption_estimates manual__2022-08-11T19:19:47.922898+00:00 [queued]>
[2022-08-11 19:25:00,320] {taskinstance.py:1179} INFO - Dependencies all met for <TaskInstance: ETL_DAG_V2.Ingest_from_food_consumption_estimates manual__2022-08-11T19:19:47.922898+00:00 [queued]>
[2022-08-11 19:25:00,321] {taskinstance.py:1376} INFO - 
--------------------------------------------------------------------------------
[2022-08-11 19:25:00,322] {taskinstance.py:1377} INFO - Starting attempt 2 of 6
[2022-08-11 19:25:00,323] {taskinstance.py:1378} INFO - 
--------------------------------------------------------------------------------
[2022-08-11 19:25:00,332] {taskinstance.py:1397} INFO - Executing <Task(PythonOperator): Ingest_from_food_consumption_estimates> on 2022-08-11 19:19:47.922898+00:00
[2022-08-11 19:25:00,339] {standard_task_runner.py:52} INFO - Started process 2125 to run task
[2022-08-11 19:25:00,346] {standard_task_runner.py:79} INFO - Running: ['***', 'tasks', 'run', 'ETL_DAG_V2', 'Ingest_from_food_consumption_estimates', 'manual__2022-08-11T19:19:47.922898+00:00', '--job-id', '480', '--raw', '--subdir', 'DAGS_FOLDER/etl_dag.py', '--cfg-path', '/tmp/tmpri39ig6o', '--error-file', '/tmp/tmpix5ur_g9']
[2022-08-11 19:25:00,349] {standard_task_runner.py:80} INFO - Job 480: Subtask Ingest_from_food_consumption_estimates
[2022-08-11 19:25:00,424] {task_command.py:371} INFO - Running <TaskInstance: ETL_DAG_V2.Ingest_from_food_consumption_estimates manual__2022-08-11T19:19:47.922898+00:00 [running]> on host ce1be8c59d56
[2022-08-11 19:25:00,506] {taskinstance.py:1591} INFO - Exporting the following env vars:
AIRFLOW_CTX_DAG_OWNER=narapady
AIRFLOW_CTX_DAG_ID=ETL_DAG_V2
AIRFLOW_CTX_TASK_ID=Ingest_from_food_consumption_estimates
AIRFLOW_CTX_EXECUTION_DATE=2022-08-11T19:19:47.922898+00:00
AIRFLOW_CTX_TRY_NUMBER=2
AIRFLOW_CTX_DAG_RUN_ID=manual__2022-08-11T19:19:47.922898+00:00
[2022-08-11 19:25:00,553] {taskinstance.py:1909} ERROR - Task failed with exception
Traceback (most recent call last):
  File "/home/airflow/.local/lib/python3.7/site-packages/airflow/operators/python.py", line 171, in execute
    return_value = self.execute_callable()
  File "/home/airflow/.local/lib/python3.7/site-packages/airflow/operators/python.py", line 189, in execute_callable
    return self.python_callable(*self.op_args, **self.op_kwargs)
  File "/opt/airflow/dags/ingest/ingestor.py", line 124, in run
    if usda:
NameError: name 'usda' is not defined
[2022-08-11 19:25:00,563] {taskinstance.py:1420} INFO - Marking task as UP_FOR_RETRY. dag_id=ETL_DAG_V2, task_id=Ingest_from_food_consumption_estimates, execution_date=20220811T191947, start_date=20220811T192500, end_date=20220811T192500
[2022-08-11 19:25:00,570] {standard_task_runner.py:97} ERROR - Failed to execute job 480 for task Ingest_from_food_consumption_estimates (name 'usda' is not defined; 2125)
[2022-08-11 19:25:00,601] {local_task_job.py:156} INFO - Task exited with return code 1
[2022-08-11 19:25:00,636] {local_task_job.py:273} INFO - 0 downstream tasks scheduled from follow-on schedule check
