[2022-08-11 06:13:37,811] {taskinstance.py:1179} INFO - Dependencies all met for <TaskInstance: ETL_DAG_V3.load_into_price_index_table manual__2022-08-11T00:43:37.451055+00:00 [queued]>
[2022-08-11 06:13:37,843] {taskinstance.py:1179} INFO - Dependencies all met for <TaskInstance: ETL_DAG_V3.load_into_price_index_table manual__2022-08-11T00:43:37.451055+00:00 [queued]>
[2022-08-11 06:13:37,850] {taskinstance.py:1376} INFO - 
--------------------------------------------------------------------------------
[2022-08-11 06:13:37,857] {taskinstance.py:1377} INFO - Starting attempt 3 of 6
[2022-08-11 06:13:37,858] {taskinstance.py:1378} INFO - 
--------------------------------------------------------------------------------
[2022-08-11 06:13:37,905] {taskinstance.py:1397} INFO - Executing <Task(S3ToSnowflakeOperator): load_into_price_index_table> on 2022-08-11 00:43:37.451055+00:00
[2022-08-11 06:13:37,921] {standard_task_runner.py:52} INFO - Started process 19764 to run task
[2022-08-11 06:13:37,942] {standard_task_runner.py:79} INFO - Running: ['***', 'tasks', 'run', 'ETL_DAG_V3', 'load_into_price_index_table', 'manual__2022-08-11T00:43:37.451055+00:00', '--job-id', '317', '--raw', '--subdir', 'DAGS_FOLDER/etl_dag.py', '--cfg-path', '/tmp/tmp1faex0n8', '--error-file', '/tmp/tmpobexxg25']
[2022-08-11 06:13:37,945] {standard_task_runner.py:80} INFO - Job 317: Subtask load_into_price_index_table
[2022-08-11 06:13:38,199] {task_command.py:371} INFO - Running <TaskInstance: ETL_DAG_V3.load_into_price_index_table manual__2022-08-11T00:43:37.451055+00:00 [running]> on host c9fcec21ee59
[2022-08-11 06:13:38,365] {taskinstance.py:1591} INFO - Exporting the following env vars:
AIRFLOW_CTX_DAG_OWNER=narapady
AIRFLOW_CTX_DAG_ID=ETL_DAG_V3
AIRFLOW_CTX_TASK_ID=load_into_price_index_table
AIRFLOW_CTX_EXECUTION_DATE=2022-08-11T00:43:37.451055+00:00
AIRFLOW_CTX_TRY_NUMBER=3
AIRFLOW_CTX_DAG_RUN_ID=manual__2022-08-11T00:43:37.451055+00:00
[2022-08-11 06:13:38,369] {s3_to_snowflake.py:135} INFO - Executing COPY command...
[2022-08-11 06:13:38,394] {base.py:68} INFO - Using connection ID 'snowflake_conn' for task execution.
[2022-08-11 06:13:38,411] {connection.py:275} INFO - Snowflake Connector for Python Version: 2.7.11, Python Version: 3.7.13, Platform: Linux-5.10.104-linuxkit-aarch64-with-debian-11.3
[2022-08-11 06:13:38,419] {connection.py:927} INFO - This connection is in OCSP Fail Open Mode. TLS Certificates would be checked for validity and revocation status. Any other Certificate Revocation related exceptions or OCSP Responder failures would be disregarded in favor of connectivity.
[2022-08-11 06:13:38,420] {connection.py:944} INFO - Setting use_openssl_only mode to False
[2022-08-11 06:13:39,897] {cursor.py:715} INFO - query: [ALTER SESSION SET autocommit=True]
[2022-08-11 06:13:40,087] {cursor.py:739} INFO - query execution done
[2022-08-11 06:13:40,092] {snowflake.py:328} INFO - Running statement: COPY INTO public.price_index
FROM @s3_stage/
files=('price-index-staged.csv')
file_format=csv_format, parameters: None
[2022-08-11 06:13:40,093] {cursor.py:715} INFO - query: [COPY INTO public.price_index FROM @s3_stage/ files=('price-index-staged.csv') fi...]
[2022-08-11 06:13:40,294] {cursor.py:739} INFO - query execution done
[2022-08-11 06:13:40,299] {connection.py:557} INFO - closed
[2022-08-11 06:13:40,443] {connection.py:560} INFO - No async queries seem to be running, deleting session
[2022-08-11 06:13:40,613] {taskinstance.py:1909} ERROR - Task failed with exception
Traceback (most recent call last):
  File "/home/airflow/.local/lib/python3.7/site-packages/airflow/providers/snowflake/transfers/s3_to_snowflake.py", line 136, in execute
    snowflake_hook.run(copy_query, self.autocommit)
  File "/home/airflow/.local/lib/python3.7/site-packages/airflow/providers/snowflake/hooks/snowflake.py", line 332, in run
    cur.execute(sql_statement)
  File "/home/airflow/.local/lib/python3.7/site-packages/snowflake/connector/cursor.py", line 804, in execute
    Error.errorhandler_wrapper(self.connection, self, error_class, errvalue)
  File "/home/airflow/.local/lib/python3.7/site-packages/snowflake/connector/errors.py", line 280, in errorhandler_wrapper
    error_value,
  File "/home/airflow/.local/lib/python3.7/site-packages/snowflake/connector/errors.py", line 331, in hand_to_other_handler
    cursor.errorhandler(connection, cursor, error_class, error_value)
  File "/home/airflow/.local/lib/python3.7/site-packages/snowflake/connector/errors.py", line 217, in default_errorhandler
    cursor=cursor,
snowflake.connector.errors.ProgrammingError: 002003 (02000): 01a635d5-0004-2869-001e-00070003423a: SQL compilation error:
Stage 'US_FOOD_NUTRITION.PUBLIC.S3_STAGE' does not exist or not authorized.
[2022-08-11 06:13:40,649] {taskinstance.py:1420} INFO - Marking task as UP_FOR_RETRY. dag_id=ETL_DAG_V3, task_id=load_into_price_index_table, execution_date=20220811T004337, start_date=20220811T061337, end_date=20220811T061340
[2022-08-11 06:13:40,665] {standard_task_runner.py:97} ERROR - Failed to execute job 317 for task load_into_price_index_table (002003 (02000): 01a635d5-0004-2869-001e-00070003423a: SQL compilation error:
Stage 'US_FOOD_NUTRITION.PUBLIC.S3_STAGE' does not exist or not authorized.; 19764)
[2022-08-11 06:13:40,720] {local_task_job.py:156} INFO - Task exited with return code 1
[2022-08-11 06:13:40,816] {local_task_job.py:273} INFO - 0 downstream tasks scheduled from follow-on schedule check
