[2022-08-11 19:35:39,830] {taskinstance.py:1179} INFO - Dependencies all met for <TaskInstance: ETL_DAG_V2.Ingest_from_food_consumption_estimates manual__2022-08-11T05:57:31.582348+00:00 [queued]>
[2022-08-11 19:35:39,889] {taskinstance.py:1179} INFO - Dependencies all met for <TaskInstance: ETL_DAG_V2.Ingest_from_food_consumption_estimates manual__2022-08-11T05:57:31.582348+00:00 [queued]>
[2022-08-11 19:35:39,896] {taskinstance.py:1376} INFO - 
--------------------------------------------------------------------------------
[2022-08-11 19:35:39,919] {taskinstance.py:1377} INFO - Starting attempt 4 of 6
[2022-08-11 19:35:39,921] {taskinstance.py:1378} INFO - 
--------------------------------------------------------------------------------
[2022-08-11 19:35:39,987] {taskinstance.py:1397} INFO - Executing <Task(PythonOperator): Ingest_from_food_consumption_estimates> on 2022-08-11 05:57:31.582348+00:00
[2022-08-11 19:35:40,026] {standard_task_runner.py:52} INFO - Started process 2924 to run task
[2022-08-11 19:35:40,045] {standard_task_runner.py:79} INFO - Running: ['***', 'tasks', 'run', 'ETL_DAG_V2', 'Ingest_from_food_consumption_estimates', 'manual__2022-08-11T05:57:31.582348+00:00', '--job-id', '498', '--raw', '--subdir', 'DAGS_FOLDER/etl_dag.py', '--cfg-path', '/tmp/tmpzqnbu7r_', '--error-file', '/tmp/tmpmronp3_b']
[2022-08-11 19:35:40,064] {standard_task_runner.py:80} INFO - Job 498: Subtask Ingest_from_food_consumption_estimates
[2022-08-11 19:35:40,324] {task_command.py:371} INFO - Running <TaskInstance: ETL_DAG_V2.Ingest_from_food_consumption_estimates manual__2022-08-11T05:57:31.582348+00:00 [running]> on host ce1be8c59d56
[2022-08-11 19:35:40,576] {taskinstance.py:1591} INFO - Exporting the following env vars:
AIRFLOW_CTX_DAG_OWNER=narapady
AIRFLOW_CTX_DAG_ID=ETL_DAG_V2
AIRFLOW_CTX_TASK_ID=Ingest_from_food_consumption_estimates
AIRFLOW_CTX_EXECUTION_DATE=2022-08-11T05:57:31.582348+00:00
AIRFLOW_CTX_TRY_NUMBER=4
AIRFLOW_CTX_DAG_RUN_ID=manual__2022-08-11T05:57:31.582348+00:00
[2022-08-11 19:35:51,105] {taskinstance.py:1909} ERROR - Task failed with exception
Traceback (most recent call last):
  File "/home/airflow/.local/lib/python3.7/site-packages/airflow/operators/python.py", line 171, in execute
    return_value = self.execute_callable()
  File "/home/airflow/.local/lib/python3.7/site-packages/airflow/operators/python.py", line 189, in execute_callable
    return self.python_callable(*self.op_args, **self.op_kwargs)
  File "/opt/airflow/dags/ingest/ingestor.py", line 132, in run
    ingestor_usda.ingest()
  File "/opt/airflow/dags/ingest/ingestor.py", line 115, in ingest
    ingest_usda(self.s3, self.source, self.bucket_name, self.category)
  File "/opt/airflow/dags/ingest/ingestor.py", line 61, in ingest_usda
    links = filter_links(source_list)[category]
KeyError: 'food_consumption_estimates'
[2022-08-11 19:35:51,122] {taskinstance.py:1420} INFO - Marking task as UP_FOR_RETRY. dag_id=ETL_DAG_V2, task_id=Ingest_from_food_consumption_estimates, execution_date=20220811T055731, start_date=20220811T193539, end_date=20220811T193551
[2022-08-11 19:35:51,136] {standard_task_runner.py:97} ERROR - Failed to execute job 498 for task Ingest_from_food_consumption_estimates ('food_consumption_estimates'; 2924)
[2022-08-11 19:35:51,218] {local_task_job.py:156} INFO - Task exited with return code 1
[2022-08-11 19:35:51,259] {local_task_job.py:273} INFO - 0 downstream tasks scheduled from follow-on schedule check
