[2022-08-08 06:08:21,370] {taskinstance.py:1179} INFO - Dependencies all met for <TaskInstance: etl_dag.Ingest manual__2022-08-08T05:32:42.206995+00:00 [queued]>
[2022-08-08 06:08:21,377] {taskinstance.py:1179} INFO - Dependencies all met for <TaskInstance: etl_dag.Ingest manual__2022-08-08T05:32:42.206995+00:00 [queued]>
[2022-08-08 06:08:21,378] {taskinstance.py:1376} INFO - 
--------------------------------------------------------------------------------
[2022-08-08 06:08:21,379] {taskinstance.py:1377} INFO - Starting attempt 3 of 6
[2022-08-08 06:08:21,380] {taskinstance.py:1378} INFO - 
--------------------------------------------------------------------------------
[2022-08-08 06:08:21,390] {taskinstance.py:1397} INFO - Executing <Task(PythonOperator): Ingest> on 2022-08-08 05:32:42.206995+00:00
[2022-08-08 06:08:21,394] {standard_task_runner.py:52} INFO - Started process 2797 to run task
[2022-08-08 06:08:21,399] {standard_task_runner.py:79} INFO - Running: ['***', 'tasks', 'run', 'etl_dag', 'Ingest', 'manual__2022-08-08T05:32:42.206995+00:00', '--job-id', '82', '--raw', '--subdir', 'DAGS_FOLDER/etl_dag.py', '--cfg-path', '/tmp/tmpwkr8570w', '--error-file', '/tmp/tmpv5tz4g1i']
[2022-08-08 06:08:21,407] {standard_task_runner.py:80} INFO - Job 82: Subtask Ingest
[2022-08-08 06:08:21,465] {task_command.py:371} INFO - Running <TaskInstance: etl_dag.Ingest manual__2022-08-08T05:32:42.206995+00:00 [running]> on host 8d3924a1d70c
[2022-08-08 06:08:21,520] {taskinstance.py:1591} INFO - Exporting the following env vars:
AIRFLOW_CTX_DAG_OWNER=narapady
AIRFLOW_CTX_DAG_ID=etl_dag
AIRFLOW_CTX_TASK_ID=Ingest
AIRFLOW_CTX_EXECUTION_DATE=2022-08-08T05:32:42.206995+00:00
AIRFLOW_CTX_TRY_NUMBER=3
AIRFLOW_CTX_DAG_RUN_ID=manual__2022-08-08T05:32:42.206995+00:00
[2022-08-08 06:08:28,627] {logging_mixin.py:115} INFO - Successfully uploaded food-at-home-and-food-away-from-home/FAH_total.xls to s3-bucket-raw-usda
[2022-08-08 06:08:30,062] {logging_mixin.py:115} INFO - Successfully uploaded food-at-home-and-food-away-from-home/FAH_gender.xls to s3-bucket-raw-usda
[2022-08-08 06:08:31,609] {logging_mixin.py:115} INFO - Successfully uploaded food-at-home-and-food-away-from-home/FAH_income.xls to s3-bucket-raw-usda
[2022-08-08 06:08:33,132] {logging_mixin.py:115} INFO - Successfully uploaded food-at-home-and-food-away-from-home/FAH_education.xls to s3-bucket-raw-usda
[2022-08-08 06:08:34,661] {logging_mixin.py:115} INFO - Successfully uploaded food-at-home-and-food-away-from-home/FAH_race.xls to s3-bucket-raw-usda
[2022-08-08 06:08:36,234] {logging_mixin.py:115} INFO - Successfully uploaded food-at-home-and-food-away-from-home/FAFH_total.xls to s3-bucket-raw-usda
[2022-08-08 06:08:36,548] {local_task_job.py:221} WARNING - State of this instance has been externally set to None. Terminating instance.
[2022-08-08 06:08:36,551] {process_utils.py:129} INFO - Sending Signals.SIGTERM to group 2797. PIDs of all processes in the group: [2797]
[2022-08-08 06:08:36,553] {process_utils.py:80} INFO - Sending the signal Signals.SIGTERM to group 2797
[2022-08-08 06:08:36,554] {taskinstance.py:1561} ERROR - Received SIGTERM. Terminating subprocesses.
[2022-08-08 06:08:36,563] {taskinstance.py:1909} ERROR - Task failed with exception
Traceback (most recent call last):
  File "/home/airflow/.local/lib/python3.7/site-packages/airflow/operators/python.py", line 171, in execute
    return_value = self.execute_callable()
  File "/home/airflow/.local/lib/python3.7/site-packages/airflow/operators/python.py", line 189, in execute_callable
    return self.python_callable(*self.op_args, **self.op_kwargs)
  File "/opt/airflow/dags/ingest/ingestor.py", line 136, in run
    ingestor_usda.ingest()
  File "/opt/airflow/dags/ingest/ingestor.py", line 118, in ingest
    ingest_usda(self.s3, self.usda_sources, self.bucket_name)
  File "/opt/airflow/dags/ingest/ingestor.py", line 56, in ingest_usda
    req = requests.get(link)
  File "/home/airflow/.local/lib/python3.7/site-packages/requests/api.py", line 73, in get
    return request("get", url, params=params, **kwargs)
  File "/home/airflow/.local/lib/python3.7/site-packages/requests/api.py", line 59, in request
    return session.request(method=method, url=url, **kwargs)
  File "/home/airflow/.local/lib/python3.7/site-packages/requests/sessions.py", line 587, in request
    resp = self.send(prep, **send_kwargs)
  File "/home/airflow/.local/lib/python3.7/site-packages/requests/sessions.py", line 701, in send
    r = adapter.send(request, **kwargs)
  File "/home/airflow/.local/lib/python3.7/site-packages/requests/adapters.py", line 499, in send
    timeout=timeout,
  File "/home/airflow/.local/lib/python3.7/site-packages/urllib3/connectionpool.py", line 710, in urlopen
    chunked=chunked,
  File "/home/airflow/.local/lib/python3.7/site-packages/urllib3/connectionpool.py", line 386, in _make_request
    self._validate_conn(conn)
  File "/home/airflow/.local/lib/python3.7/site-packages/urllib3/connectionpool.py", line 1040, in _validate_conn
    conn.connect()
  File "/home/airflow/.local/lib/python3.7/site-packages/urllib3/connection.py", line 424, in connect
    tls_in_tls=tls_in_tls,
  File "/home/airflow/.local/lib/python3.7/site-packages/urllib3/util/ssl_.py", line 450, in ssl_wrap_socket
    sock, context, tls_in_tls, server_hostname=server_hostname
  File "/home/airflow/.local/lib/python3.7/site-packages/urllib3/util/ssl_.py", line 493, in _ssl_wrap_socket_impl
    return ssl_context.wrap_socket(sock, server_hostname=server_hostname)
  File "/usr/local/lib/python3.7/ssl.py", line 423, in wrap_socket
    session=session
  File "/usr/local/lib/python3.7/ssl.py", line 870, in _create
    self.do_handshake()
  File "/usr/local/lib/python3.7/ssl.py", line 1139, in do_handshake
    self._sslobj.do_handshake()
  File "/home/airflow/.local/lib/python3.7/site-packages/airflow/models/taskinstance.py", line 1563, in signal_handler
    raise AirflowException("Task received SIGTERM signal")
airflow.exceptions.AirflowException: Task received SIGTERM signal
[2022-08-08 06:08:36,570] {taskinstance.py:1420} INFO - Marking task as UP_FOR_RETRY. dag_id=etl_dag, task_id=Ingest, execution_date=20220808T053242, start_date=20220808T060821, end_date=20220808T060836
[2022-08-08 06:08:36,578] {standard_task_runner.py:97} ERROR - Failed to execute job 82 for task Ingest ((psycopg2.errors.ForeignKeyViolation) insert or update on table "task_fail" violates foreign key constraint "task_fail_ti_fkey"
DETAIL:  Key (dag_id, task_id, run_id, map_index)=(etl_dag, Ingest, manual__2022-08-08T05:32:42.206995+00:00, -1) is not present in table "task_instance".

[SQL: INSERT INTO task_fail (task_id, dag_id, run_id, map_index, start_date, end_date, duration) VALUES (%(task_id)s, %(dag_id)s, %(run_id)s, %(map_index)s, %(start_date)s, %(end_date)s, %(duration)s) RETURNING task_fail.id]
[parameters: {'task_id': 'Ingest', 'dag_id': 'etl_dag', 'run_id': 'manual__2022-08-08T05:32:42.206995+00:00', 'map_index': -1, 'start_date': datetime.datetime(2022, 8, 8, 6, 8, 21, 372021, tzinfo=Timezone('UTC')), 'end_date': datetime.datetime(2022, 8, 8, 6, 8, 36, 570180, tzinfo=Timezone('UTC')), 'duration': 15}]
(Background on this error at: https://sqlalche.me/e/14/gkpj); 2797)
[2022-08-08 06:08:36,607] {process_utils.py:75} INFO - Process psutil.Process(pid=2797, status='terminated', exitcode=1, started='06:08:21') (2797) terminated with exit code 1
